Workbook

Sheet About
A1: BESP BAU EV Subsidy Percentage | B1: Massachusetts | C1: 44819 | F1: State | G1: State
B2: =LOOKUP(B1,F2:G51,G2:G51) -> MA | F2: Alabama | G2: AL
A3: Sources: | B3: Federal Tax Credit Methodology | F3: Alaska | G3: AK
B4: Ernst and Young | F4: Arizona | G4: AZ
B5: 2019 | F5: Arkansas | G5: AR
B6: Federal revenue estimates for potential changes to the plug-in electric drive vehicle tax credit | F6: California | G6: CA
B7: https://www.afpm.org/sites/default/files/issue_resources/EV-Tax-May2019.pdf | F7: Colorado | G7: CO
F8: Connecticut | G8: CT
B9: Historial Sales by Manufacturer | F9: Delaware | G9: DE
B10: EVAdopotion.com | F10: Florida | G10: FL
B11: 2019 | F11: Georgia | G11: GA
B12: Federal EV Tax Credit Phase Out Tracker by Automaker | F12: Hawaii | G12: HI
B13: https://evadoption.com/ev-sales/federal-ev-tax-credit-phase-out-tracker-by-automaker/ | F13: Idaho | G13: ID
F14: Illinois | G14: IL
B15: 2019 Sales by Manufacturer | F15: Indiana | G15: IN
B16: InsideEVs | F16: Iowa | G16: IA
B17: 2019 | F17: Kansas | G17: KS
B18: Final Update: Monthly Plug-In EV Sales Scorecard: May 2019 | F18: Kentucky | G18: KY
B19: https://insideevs.com/news/352626/ev-sales-scorecard-may-2019/ | F19: Louisiana | G19: LA
F20: Maine | G20: ME
B21: State Rebate Amounts | F21: Maryland | G21: MD
B22: Yamauchi, Mia | F22: Massachusetts | G22: MA
B23: 2017 | F23: Michigan | G23: MI
B24: Updated 2017 Incentives for Electric Vehicles and EVSE (for Tesla and More) | F24: Minnesota | G24: MN
B25: https://www.pluglesspower.com/learn/updated-2017-incentives-electric-vehicles-evse-state-federal-tax-credits-grants-loans-rebates/ | F25: Mississippi | G25: MS
F26: Missouri | G26: MO
B27: Population by U.S. State | F27: Montana | G27: MT
B28: Wikipedia (with data from U.S. Census Bureau) | F28: Nebraska | G28: NE
B29: 2017 | F29: Nevada | G29: NV
B30: List of U.S. states and territories by population | F30: New Hampshire | G30: NH
B31: https://en.wikipedia.org/wiki/List_of_U.S._states_and_territories_by_population | F31: New Jersey | G31: NJ
F32: New Mexico | G32: NM
A33: Notes | F33: New York | G33: NY
A34: The U.S. only has BAU subsidies for passenger LDVs, not other vehicle types. | F34: North Carolina | G34: NC
A35: We account for both federal and state-level subsidies for EVs but not for | F35: North Dakota | G35: ND
A36: charging equipment. | F36: Ohio | G36: OH
F37: Oklahoma | G37: OK
A38: For assumptions governing EV tax credit phase-out, see the "Data" tab. | F38: Oregon | G38: OR
F39: Pennsylvania | G39: PA
A40: The file expressely excludes the IRA related subsidies - more modeling is required to understand | F40: Rhode Island | G40: RI
...

Sheet Data
A1: Federal EV Subsidy Amount
A2: 2019 | B2: 2020 | C2: 2021 | D2: 2022 | E2: 2023 | F2: 2024 | G2: 2025 | H2: 2026 | I2: 2027 | J2: 2028 | K2: 2029 | L2: 2030 | M2: 2031 | N2: 2032 | O2: 2033 | P2: 2034 | Q2: 2035 | R2: 2036 | S2: 2037 | T2: 2038 | U2: 2039 | V2: 2040 | W2: 2041 | X2: 2042 | Y2: 2043 | Z2: 2044 | AA2: 2045 | AB2: 2046 | AC2: 2047 | AD2: 2048 | AE2: 2049 | AF2: 2050
A3: =BAU!C92 -> 2745.8606 | B3: =BAU!D92 -> 2745.8606 | C3: =BAU!E92 -> 2745.8606 | D3: =BAU!F92 -> 1913.0458 | E3: =BAU!G92 -> 1531.9112 | F3: =BAU!H92 -> 1131.4323 | G3: =BAU!I92 -> 933.18814 | H3: =BAU!J92 -> 933.18814 | ... AF3: =BAU!AH92 -> 0
E4: Note: this does not include the IRA subsidies
A5: State EV Subsidy Amounts
A6: This list only includes rebates on the EV itself, not on charging equipment.
A7: It also omits states that do not offer a rebate but do exempt EVs from sales, use, or excise taxes.
A8: Rebate | B8: State | C8: Population (July 1, 2016)
A9: 2500 | B9: California | C9: 39250017
A10: 5000 | B10: Colorado | C10: 5540545
A11: 3500 | B11: Delaware | C11: 952065
A12: 1500 | B12: Louisiana | C12: 4681666
A13: 2500 | B13: Massachusetts | C13: 6811779
A14: 1500 | B14: Oklahoma | C14: 3923561
A15: 2500 | B15: Rhode Island | C15: 1056426
A16: Note: Pennsylvania offers a $1750 rebate, but only to the first 250 qualified applicants.
B18: 50 States + DC | C18: 323127513
B19: Uncovered Pop | C19: =C18-SUM(C9:C15) -> 260911454
A21: State Ave Tax Credit | C21: =About!B2 -> MA
C22: 2020 | D22: =C22+1 -> 2021 | E22: =D22+1 -> 2022 | F22: =E22+1 -> 2023 | G22: =F22+1 -> 2024 | H22: =G22+1 -> 2025 | I22: =H22+1 -> 2026
B23: LDV | C23: =SUMIFS(C$41:C$54,$A$41:$A$54,$C$21,$B$41:$B$54,$B23) -> 2500 | D23: =SUMIFS(D$41:D$54,$A$41:$A$54,$C$21,$B$41:$B$54,$B23) -> 2500 | E23: =SUMIFS(E$41:E$54,$A$41:$A$54,$C$21,$B$41:$B$54,$B23) -> 2500 | F23: =SUMIFS(F$41:F$54,$A$41:$A$54,$C$21,$B$41:$B$54,$B23) -> 2500 | G23: =SUMIFS(G$41:G$54,$A$41:$A$54,$C$21,$B$41:$B$54,$B23) -> 2500 | H23: =SUMIFS(H$41:H$54,$A$41:$A$54,$C$21,$B$41:$B$54,$B23) -> 2500 | I23: =SUMIFS(I$41:I$54,$A$41:$A$54,$C$21,$B$41:$B$54,$B23) -> 2500
B24: HDV | C24: =SUMIFS(C$41:C$54,$A$41:$A$54,$C$21,$B$41:$B$54,$B24) -> 0 | D24: =SUMIFS(D$41:D$54,$A$41:$A$54,$C$21,$B$41:$B$54,$B24) -> 0 | E24: =SUMIFS(E$41:E$54,$A$41:$A$54,$C$21,$B$41:$B$54,$B24) -> 0 | F24: =SUMIFS(F$41:F$54,$A$41:$A$54,$C$21,$B$41:$B$54,$B24) -> 0 | G24: =SUMIFS(G$41:G$54,$A$41:$A$54,$C$21,$B$41:$B$54,$B24) -> 0 | H24: =SUMIFS(H$41:H$54,$A$41:$A$54,$C$21,$B$41:$B$54,$B24) -> 0 | I24: =SUMIFS(I$41:I$54,$A$41:$A$54,$C$21,$B$41:$B$54,$B24) -> 0
B26: =C23*About!A45 -> 2217.7767
A27: Note: Average truck price from Statista-- approximattion
A28: Time (Year) | B28: 2018 | C28: 2019 | D28: 2020 | E28: 2021 | F28: 2022 | G28: 2023 | H28: 2024 | I28: 2025 | J28: 2026 | K28: 2027 | L28: 2028 | M28: 2029 | N28: 2030 | O28: 2031 | P28: 2032 | Q28: 2033 | R28: 2034 | S28: 2035 | T28: 2036 | U28: 2037 | V28: 2038 | W28: 2039 | X28: 2040 | Y28: 2041 | Z28: 2042 | AA28: 2043 | AB28: 2044 | AC28: 2045 | AD28: 2046 | AE28: 2047 | AF28: 2048 | AG28: 2049 | AH28: 2050
A29: New Vehicle Price after Carbon Tax[LDVs,passenger,battery electric vehicle] : MostRecentRun | B29: 53703 | C29: 51776.5 | D29: 50407.6 | E29: 49301.3 | F29: 48343.4 | G29: 47462.2 | H29: 46667.2 | I29: 45962.6 | J29: 45330.9 | K29: 44750.2 | L29: 44223.9 | M29: 43738.9 | N29: 43295.4 | O29: 42905 | P29: 42563.2 | Q29: 42259.5 | R29: 41992 | S29: 41757.9 | T29: 41553.7 | U29: 41372.7 | V29: 41211.3 | W29: 41067.5 | X29: 40939.8 | Y29: 40826.3 | Z29: 40724.3 | AA29: 40632.3 | AB29: 40548.8 | AC29: 40472.8 | AD29: 40403.2 | AE29: 40339.3 | AF29: 40280.3 | AG29: 40225.5 | AH29: 40174.6
A30: Average truck | B30: 117430 | C30: 117430 | D30: 117430 | E30: 117430 | F30: 117430 | G30: 117430 | H30: 117430 | I30: 117430 | J30: 117430 | K30: 117430 | L30: 117430 | M30: 117430 | N30: 117430 | O30: 117430 | P30: 117430 | Q30: 117430 | R30: 117430 | S30: 117430 | T30: 117430 | U30: 117430 | V30: 117430 | W30: 117430 | X30: 117430 | Y30: 117430 | Z30: 117430 | AA30: 117430 | AB30: 117430 | AC30: 117430 | AD30: 117430 | AE30: 117430 | AF30: 117430 | AG30: 117430 | AH30: 117430
A31: Approximate EV Subsidy Percentage LDV
A32: 2019 | B32: 2020 | C32: 2021 | D32: 2022 | E32: 2023 | F32: 2024 | G32: 2025 | H32: 2026 | I32: 2027 | J32: 2028 | K32: 2029 | L32: 2030 | M32: 2031 | N32: 2032 | O32: 2033 | P32: 2034 | Q32: 2035 | R32: 2036 | S32: 2037 | T32: 2038 | U32: 2039 | V32: 2040 | W32: 2041 | X32: 2042 | Y32: 2043 | Z32: 2044 | AA32: 2045 | AB32: 2046 | AC32: 2047 | AD32: 2048 | AE32: 2049 | AF32: 2050
A33: =(A3+C23) -> 5245.8606 | B33: =(B3+C23) -> 5245.8606 | C33: =(C3+D23) -> 5245.8606 | D33: =(D3+E23) -> 4413.0458 | E33: =(E3+F23) -> 4031.9112 | F33: =(F3+G23) -> 3631.4323 | G33: =(G3+H23) -> 3433.1881 | H33: =(H3+I23) -> 3433.1881 | I33: =(I3+J23) -> 744.00736 | ... AF33: =(AF3+AG23) -> 0
A34: Approximate EV Subsidy Percentage HDV
A35: 0 | B35: =C24/D30 -> 0 | C35: =D24/E30 -> 0 | D35: =E24/F30 -> 0 | E35: =F24/G30 -> 0 | F35: =G24/H30 -> 0 | G35: =H24/I30 -> 0 | H35: =I24/J30 -> 0 | I35: =J24/K30 -> 0 | ... AF35: =AG24/AH30 -> 0
A36: State Rebates + Tax Credits Updated 8/11/2021
A37: TC | B37: https://www.energysage.com/electric-vehicles/costs-and-benefits-evs/ev-tax-credits/
A38: Rebates | B38: https://www.tesla.com/support/incentives
A39: Note: Could be an optimistic estimate
A40: State | B40: Category | C40: 2020 | D40: =C40+1 -> 2021 | E40: =D40+1 -> 2022 | F40: =E40+1 -> 2023 | G40: =F40+1 -> 2024 | H40: =G40+1 -> 2025 | I40: =H40+1 -> 2026
A41: CO | B41: LDV | C41: 4750 | D41: 4750 | E41: 3000 | F41: 3000 | G41: 2400 | H41: 2400 | I41: 2400 | J41: Note: average of cars and truck subsidies, which are different
A42: CO | B42: HDV | C42: 8000 | D42: 8000 | E42: 5000 | F42: 5000 | G42: 4000 | H42: 4000 | I42: 4000 | J42: Colorado source: https://afdc.energy.gov/laws/11702
A43: CT | B43: LDV | C43: 2250 | D43: 2250 | E43: 2250 | F43: 2250 | G43: 2250 | H43: 2250 | I43: 2250 | Q43: https://afdc.energy.gov/laws/11609
...

Sheet BAU
D1: Projected Cumulative Sales
B2: Cumulative Sales through 2019 | C2: Cumulative Sales through 12/2018 | D2: 2019 | E2: 2020 | F2: 2021 | G2: 2022 | H2: 2023 | I2: 2024 | J2: 2025 | K2: 2026 | L2: 2027 | M2: 2028 | N2: 2029 | O2: 2030 | P2: 2031 | Q2: 2032 | R2: 2033 | S2: 2034 | T2: 2035 | U2: 2036 | V2: 2037 | W2: 2038 | X2: 2039 | Y2: 2040 | Z2: 2041 | AA2: 2042 | AB2: 2043 | AC2: 2044 | AD2: 2045 | AE2: 2046 | AF2: 2047 | AG2: 2048 | AH2: 2049 | AI2: 2050
A3: Honda | B3: {=INDEX('Cumulative Sales'!$B$5:$B$21,MATCH(A3,'Cumulative Sales'!$A$5:$A$21,0),1)} -> 27636 | C3: =B3-INDEX($K$23:$K$40,MATCH(A3,$G$23:$G$40,0)) -> 23682 | D3: =C3+SUMIFS(C$50:C$66,$A$50:$A$66,$A3) -> 37377.416 | E3: =D3+SUMIFS(D$50:D$66,$A$50:$A$66,$A3) -> 55507.735 | F3: =E3+SUMIFS(E$50:E$66,$A$50:$A$66,$A3) -> 79340.233 | G3: =F3+SUMIFS(F$50:F$66,$A$50:$A$66,$A3) -> 110413.39 | H3: =G3+SUMIFS(G$50:G$66,$A$50:$A$66,$A3) -> 149790.23 | I3: =H3+SUMIFS(H$50:H$66,$A$50:$A$66,$A3) -> 200274.6 | J3: =I3+SUMIFS(I$50:I$66,$A$50:$A$66,$A3) -> 264097.85 | K3: =J3+SUMIFS(J$50:J$66,$A$50:$A$66,$A3) -> 346384.4 | ... AI3: =AH3+SUMIFS(AH$50:AH$66,$A$50:$A$66,$A3) -> 10491285
A4: Audi | B4: {=INDEX('Cumulative Sales'!$B$5:$B$21,MATCH(A4,'Cumulative Sales'!$A$5:$A$21,0),1)} -> 10218 | C4: =B4-INDEX($K$23:$K$40,MATCH(A4,$G$23:$G$40,0)) -> 9788 | D4: =C4+SUMIFS(C$50:C$66,$A$50:$A$66,$A4) -> 13363.935 | E4: =D4+SUMIFS(D$50:D$66,$A$50:$A$66,$A4) -> 18097.844 | F4: =E4+SUMIFS(E$50:E$66,$A$50:$A$66,$A4) -> 24320.617 | G4: =F4+SUMIFS(F$50:F$66,$A$50:$A$66,$A4) -> 32433.96 | H4: =G4+SUMIFS(G$50:G$66,$A$50:$A$66,$A4) -> 42715.433 | I4: =H4+SUMIFS(H$50:H$66,$A$50:$A$66,$A4) -> 55897.13 | J4: =I4+SUMIFS(I$50:I$66,$A$50:$A$66,$A4) -> 72561.67 | K4: =J4+SUMIFS(J$50:J$66,$A$50:$A$66,$A4) -> 94047.063 | ... AI4: =AH4+SUMIFS(AH$50:AH$66,$A$50:$A$66,$A4) -> 2742926.6
A5: BMW | B5: {=INDEX('Cumulative Sales'!$B$5:$B$21,MATCH(A5,'Cumulative Sales'!$A$5:$A$21,0),1)} -> 85888 | C5: =B5-INDEX($K$23:$K$40,MATCH(A5,$G$23:$G$40,0)) -> 82633 | D5: =C5+SUMIFS(C$50:C$66,$A$50:$A$66,$A5) -> 95666.891 | E5: =D5+SUMIFS(D$50:D$66,$A$50:$A$66,$A5) -> 112921.47 | F5: =E5+SUMIFS(E$50:E$66,$A$50:$A$66,$A5) -> 135602.79 | G5: =F5+SUMIFS(F$50:F$66,$A$50:$A$66,$A5) -> 165175.03 | H5: =G5+SUMIFS(G$50:G$66,$A$50:$A$66,$A5) -> 202649.87 | I5: =H5+SUMIFS(H$50:H$66,$A$50:$A$66,$A5) -> 250695.71 | J5: =I5+SUMIFS(I$50:I$66,$A$50:$A$66,$A5) -> 311436.13 | K5: =J5+SUMIFS(J$50:J$66,$A$50:$A$66,$A5) -> 389748.02 | ... AI5: =AH5+SUMIFS(AH$50:AH$66,$A$50:$A$66,$A5) -> 10044623
A6: FCA | B6: {=INDEX('Cumulative Sales'!$B$5:$B$21,MATCH(A6,'Cumulative Sales'!$A$5:$A$21,0),1)} -> 39855 | C6: =B6-INDEX($K$23:$K$40,MATCH(A6,$G$23:$G$40,0)) -> 39663 | D6: =C6+SUMIFS(C$50:C$66,$A$50:$A$66,$A6) -> 40292.143 | E6: =D6+SUMIFS(D$50:D$66,$A$50:$A$66,$A6) -> 41125.017 | F6: =E6+SUMIFS(E$50:E$66,$A$50:$A$66,$A6) -> 42219.838 | G6: =F6+SUMIFS(F$50:F$66,$A$50:$A$66,$A6) -> 43647.283 | H6: =G6+SUMIFS(G$50:G$66,$A$50:$A$66,$A6) -> 45456.183 | I6: =H6+SUMIFS(H$50:H$66,$A$50:$A$66,$A6) -> 47775.344 | J6: =I6+SUMIFS(I$50:I$66,$A$50:$A$66,$A6) -> 50707.268 | K6: =J6+SUMIFS(J$50:J$66,$A$50:$A$66,$A6) -> 54487.363 | ... AI6: =AH6+SUMIFS(AH$50:AH$66,$A$50:$A$66,$A6) -> 520525.68
A7: Ford | B7: {=INDEX('Cumulative Sales'!$B$5:$B$21,MATCH(A7,'Cumulative Sales'!$A$5:$A$21,0),1)} -> 114247 | C7: =B7-INDEX($K$23:$K$40,MATCH(A7,$G$23:$G$40,0)) -> 112506 | D7: =C7+SUMIFS(C$50:C$66,$A$50:$A$66,$A7) -> 119285.47 | E7: =D7+SUMIFS(D$50:D$66,$A$50:$A$66,$A7) -> 128260.3 | F7: =E7+SUMIFS(E$50:E$66,$A$50:$A$66,$A7) -> 140057.81 | G7: =F7+SUMIFS(F$50:F$66,$A$50:$A$66,$A7) -> 155439.58 | H7: =G7+SUMIFS(G$50:G$66,$A$50:$A$66,$A7) -> 174931.81 | I7: =H7+SUMIFS(H$50:H$66,$A$50:$A$66,$A7) -> 199922.47 | J7: =I7+SUMIFS(I$50:I$66,$A$50:$A$66,$A7) -> 231516.11 | K7: =J7+SUMIFS(J$50:J$66,$A$50:$A$66,$A7) -> 272249.41 | ... AI7: =AH7+SUMIFS(AH$50:AH$66,$A$50:$A$66,$A7) -> 5294155
A8: GM | B8: {=INDEX('Cumulative Sales'!$B$5:$B$21,MATCH(A8,'Cumulative Sales'!$A$5:$A$21,0),1)} -> 211587 | C8: =B8-INDEX($K$23:$K$40,MATCH(A8,$G$23:$G$40,0)) -> 203331 | D8: =C8+SUMIFS(C$50:C$66,$A$50:$A$66,$A8) -> 231350.98 | E8: =D8+SUMIFS(D$50:D$66,$A$50:$A$66,$A8) -> 268444.49 | F8: =E8+SUMIFS(E$50:E$66,$A$50:$A$66,$A8) -> 317204.3 | G8: =F8+SUMIFS(F$50:F$66,$A$50:$A$66,$A8) -> 380778.06 | H8: =G8+SUMIFS(G$50:G$66,$A$50:$A$66,$A8) -> 461340.65 | I8: =H8+SUMIFS(H$50:H$66,$A$50:$A$66,$A8) -> 564628.54 | J8: =I8+SUMIFS(I$50:I$66,$A$50:$A$66,$A8) -> 695206.97 | K8: =J8+SUMIFS(J$50:J$66,$A$50:$A$66,$A8) -> 863560.17 | ... AI8: =AH8+SUMIFS(AH$50:AH$66,$A$50:$A$66,$A8) -> 21619399
A9: Hyundai | B9: {=INDEX('Cumulative Sales'!$B$5:$B$21,MATCH(A9,'Cumulative Sales'!$A$5:$A$21,0),1)} -> 9157 | C9: =B9-INDEX($K$23:$K$40,MATCH(A9,$G$23:$G$40,0)) -> 8617 | D9: =C9+SUMIFS(C$50:C$66,$A$50:$A$66,$A9) -> 10906.894 | E9: =D9+SUMIFS(D$50:D$66,$A$50:$A$66,$A9) -> 13938.31 | F9: =E9+SUMIFS(E$50:E$66,$A$50:$A$66,$A9) -> 17923.139 | G9: =F9+SUMIFS(F$50:F$66,$A$50:$A$66,$A9) -> 23118.617 | H9: =G9+SUMIFS(G$50:G$66,$A$50:$A$66,$A9) -> 29702.484 | I9: =H9+SUMIFS(H$50:H$66,$A$50:$A$66,$A9) -> 38143.545 | J9: =I9+SUMIFS(I$50:I$66,$A$50:$A$66,$A9) -> 48814.887 | K9: =J9+SUMIFS(J$50:J$66,$A$50:$A$66,$A9) -> 62573.321 | ... AI9: =AH9+SUMIFS(AH$50:AH$66,$A$50:$A$66,$A9) -> 1758815.7
A10: Kia | B10: {=INDEX('Cumulative Sales'!$B$5:$B$21,MATCH(A10,'Cumulative Sales'!$A$5:$A$21,0),1)} -> 13325 | C10: =B10-INDEX($K$23:$K$40,MATCH(A10,$G$23:$G$40,0)) -> 12259 | D10: =C10+SUMIFS(C$50:C$66,$A$50:$A$66,$A10) -> 16434.009 | E10: =D10+SUMIFS(D$50:D$66,$A$50:$A$66,$A10) -> 21960.985 | F10: =E10+SUMIFS(E$50:E$66,$A$50:$A$66,$A10) -> 29226.254 | G10: =F10+SUMIFS(F$50:F$66,$A$50:$A$66,$A10) -> 38698.817 | H10: =G10+SUMIFS(G$50:G$66,$A$50:$A$66,$A10) -> 50702.736 | I10: =H10+SUMIFS(H$50:H$66,$A$50:$A$66,$A10) -> 66092.751 | J10: =I10+SUMIFS(I$50:I$66,$A$50:$A$66,$A10) -> 85549.087 | K10: =J10+SUMIFS(J$50:J$66,$A$50:$A$66,$A10) -> 110633.91 | ... AI10: =AH10+SUMIFS(AH$50:AH$66,$A$50:$A$66,$A10) -> 3203277.9
A11: Mercedes | B11: {=INDEX('Cumulative Sales'!$B$5:$B$21,MATCH(A11,'Cumulative Sales'!$A$5:$A$21,0),1)} -> 19193 | C11: =B11-INDEX($K$23:$K$40,MATCH(A11,$G$23:$G$40,0)) -> 17881 | D11: =C11+SUMIFS(C$50:C$66,$A$50:$A$66,$A11) -> 24350.529 | E11: =D11+SUMIFS(D$50:D$66,$A$50:$A$66,$A11) -> 32915.045 | F11: =E11+SUMIFS(E$50:E$66,$A$50:$A$66,$A11) -> 44173.193 | G11: =F11+SUMIFS(F$50:F$66,$A$50:$A$66,$A11) -> 58851.73 | H11: =G11+SUMIFS(G$50:G$66,$A$50:$A$66,$A11) -> 77452.817 | I11: =H11+SUMIFS(H$50:H$66,$A$50:$A$66,$A11) -> 101300.95 | J11: =I11+SUMIFS(I$50:I$66,$A$50:$A$66,$A11) -> 131450.18 | K11: =J11+SUMIFS(J$50:J$66,$A$50:$A$66,$A11) -> 170321.23 | ... AI11: =AH11+SUMIFS(AH$50:AH$66,$A$50:$A$66,$A11) -> 4962634.4
A12: Mitsubishi | B12: {=INDEX('Cumulative Sales'!$B$5:$B$21,MATCH(A12,'Cumulative Sales'!$A$5:$A$21,0),1)} -> 7004 | C12: =B12-INDEX($K$23:$K$40,MATCH(A12,$G$23:$G$40,0)) -> 6373 | D12: =C12+SUMIFS(C$50:C$66,$A$50:$A$66,$A12) -> 8746.1628 | E12: =D12+SUMIFS(D$50:D$66,$A$50:$A$66,$A12) -> 11887.812 | F12: =E12+SUMIFS(E$50:E$66,$A$50:$A$66,$A12) -> 16017.544 | G12: =F12+SUMIFS(F$50:F$66,$A$50:$A$66,$A12) -> 21401.949 | H12: =G12+SUMIFS(G$50:G$66,$A$50:$A$66,$A12) -> 28225.229 | I12: =H12+SUMIFS(H$50:H$66,$A$50:$A$66,$A12) -> 36973.238 | J12: =I12+SUMIFS(I$50:I$66,$A$50:$A$66,$A12) -> 48032.629 | K12: =J12+SUMIFS(J$50:J$66,$A$50:$A$66,$A12) -> 62291.369 | ... AI12: =AH12+SUMIFS(AH$50:AH$66,$A$50:$A$66,$A12) -> 1820215.3
A13: Nissan | B13: {=INDEX('Cumulative Sales'!$B$5:$B$21,MATCH(A13,'Cumulative Sales'!$A$5:$A$21,0),1)} -> 132227 | C13: =B13-INDEX($K$23:$K$40,MATCH(A13,$G$23:$G$40,0)) -> 129542 | D13: =C13+SUMIFS(C$50:C$66,$A$50:$A$66,$A13) -> 140764.79 | E13: =D13+SUMIFS(D$50:D$66,$A$50:$A$66,$A13) -> 155621.8 | F13: =E13+SUMIFS(E$50:E$66,$A$50:$A$66,$A13) -> 175151.48 | G13: =F13+SUMIFS(F$50:F$66,$A$50:$A$66,$A13) -> 200614.57 | H13: =G13+SUMIFS(G$50:G$66,$A$50:$A$66,$A13) -> 232882.17 | I13: =H13+SUMIFS(H$50:H$66,$A$50:$A$66,$A13) -> 274251.9 | J13: =I13+SUMIFS(I$50:I$66,$A$50:$A$66,$A13) -> 326552.25 | K13: =J13+SUMIFS(J$50:J$66,$A$50:$A$66,$A13) -> 393982.48 | ... AI13: =AH13+SUMIFS(AH$50:AH$66,$A$50:$A$66,$A13) -> 8707283.7
A14: Porsche | B14: {=INDEX('Cumulative Sales'!$B$5:$B$21,MATCH(A14,'Cumulative Sales'!$A$5:$A$21,0),1)} -> 10712 | C14: =B14-INDEX($K$23:$K$40,MATCH(A14,$G$23:$G$40,0)) -> 9932 | D14: =C14+SUMIFS(C$50:C$66,$A$50:$A$66,$A14) -> 12892.671 | E14: =D14+SUMIFS(D$50:D$66,$A$50:$A$66,$A14) -> 16812.078 | F14: =E14+SUMIFS(E$50:E$66,$A$50:$A$66,$A14) -> 21964.18 | G14: =F14+SUMIFS(F$50:F$66,$A$50:$A$66,$A14) -> 28681.565 | H14: =G14+SUMIFS(G$50:G$66,$A$50:$A$66,$A14) -> 37194.04 | I14: =H14+SUMIFS(H$50:H$66,$A$50:$A$66,$A14) -> 48107.735 | J14: =I14+SUMIFS(I$50:I$66,$A$50:$A$66,$A14) -> 61905.026 | K14: =J14+SUMIFS(J$50:J$66,$A$50:$A$66,$A14) -> 79693.708 | ... AI14: =AH14+SUMIFS(AH$50:AH$66,$A$50:$A$66,$A14) -> 2272815.2
... A16: Toyota | B16: {=INDEX('Cumulative Sales'!$B$5:$B$21,MATCH(A16,'Cumulative Sales'!$A$5:$A$21,0),1)} -> 99918 | C16: =B16-INDEX($K$23:$K$40,MATCH(A16,$G$23:$G$40,0)) -> 95770 | D16: =C16+SUMIFS(C$50:C$66,$A$50:$A$66,$A16) -> 113027.47 | E16: =D16+SUMIFS(D$50:D$66,$A$50:$A$66,$A16) -> 135873.33 | F16: =E16+SUMIFS(E$50:E$66,$A$50:$A$66,$A16) -> 165904.45 | G16: =F16+SUMIFS(F$50:F$66,$A$50:$A$66,$A16) -> 205059.46 | H16: =G16+SUMIFS(G$50:G$66,$A$50:$A$66,$A16) -> 254677.87 | I16: =H16+SUMIFS(H$50:H$66,$A$50:$A$66,$A16) -> 318292.78 | J16: =I16+SUMIFS(I$50:I$66,$A$50:$A$66,$A16) -> 398715.9 | K16: =J16+SUMIFS(J$50:J$66,$A$50:$A$66,$A16) -> 502404.46 | ... AI16: =AH16+SUMIFS(AH$50:AH$66,$A$50:$A$66,$A16) -> 13285904
A17: VW | B17: {=INDEX('Cumulative Sales'!$B$5:$B$21,MATCH(A17,'Cumulative Sales'!$A$5:$A$21,0),1)} -> 14277 | C17: =B17-INDEX($K$23:$K$41,MATCH(A17,$G$23:$G$41,0)) -> 13414 | D17: =C17+SUMIFS(C$50:C$66,$A$50:$A$66,$A17) -> 16945.988 | E17: =D17+SUMIFS(D$50:D$66,$A$50:$A$66,$A17) -> 21621.718 | F17: =E17+SUMIFS(E$50:E$66,$A$50:$A$66,$A17) -> 27768.015 | G17: =F17+SUMIFS(F$50:F$66,$A$50:$A$66,$A17) -> 35781.646 | H17: =G17+SUMIFS(G$50:G$66,$A$50:$A$66,$A17) -> 45936.762 | I17: =H17+SUMIFS(H$50:H$66,$A$50:$A$66,$A17) -> 58956.459 | J17: =I17+SUMIFS(I$50:I$66,$A$50:$A$66,$A17) -> 75416.196 | K17: =J17+SUMIFS(J$50:J$66,$A$50:$A$66,$A17) -> 96637.538 | ... AI17: =AH17+SUMIFS(AH$50:AH$66,$A$50:$A$66,$A17) -> 2712963
A18: Volvo | B18: {=INDEX('Cumulative Sales'!$B$5:$B$21,MATCH(A18,'Cumulative Sales'!$A$5:$A$21,0),1)} -> 9841 | C18: =B18-INDEX($K$23:$K$40,MATCH(A18,$G$23:$G$40,0)) -> 9036 | D18: =C18+SUMIFS(C$50:C$66,$A$50:$A$66,$A18) -> 12019.801 | E18: =D18+SUMIFS(D$50:D$66,$A$50:$A$66,$A18) -> 15969.829 | F18: =E18+SUMIFS(E$50:E$66,$A$50:$A$66,$A18) -> 21162.181 | G18: =F18+SUMIFS(F$50:F$66,$A$50:$A$66,$A18) -> 27932.046 | H18: =G18+SUMIFS(G$50:G$66,$A$50:$A$66,$A18) -> 36511.025 | I18: =H18+SUMIFS(H$50:H$66,$A$50:$A$66,$A18) -> 47509.983 | J18: =I18+SUMIFS(I$50:I$66,$A$50:$A$66,$A18) -> 61415.065 | K18: =J18+SUMIFS(J$50:J$66,$A$50:$A$66,$A18) -> 79342.722 | ... AI18: =AH18+SUMIFS(AH$50:AH$66,$A$50:$A$66,$A18) -> 2289598
A19: Other | B19: =SUM('Cumulative Sales'!B5:B21)-SUM(B3:B18) -> 1001 | C19: =B19 -> 1001 | D19: =C19+SUMIFS(C$50:C$66,$A$50:$A$66,$A19) -> 3924.6626 | E19: =D19+SUMIFS(D$50:D$66,$A$50:$A$66,$A19) -> 7795.0769 | F19: =E19+SUMIFS(E$50:E$66,$A$50:$A$66,$A19) -> 12882.778 | G19: =F19+SUMIFS(F$50:F$66,$A$50:$A$66,$A19) -> 19516.196 | H19: =G19+SUMIFS(G$50:G$66,$A$50:$A$66,$A19) -> 27922.264 | I19: =H19+SUMIFS(H$50:H$66,$A$50:$A$66,$A19) -> 38699.538 | J19: =I19+SUMIFS(I$50:I$66,$A$50:$A$66,$A19) -> 52324.363 | K19: =J19+SUMIFS(J$50:J$66,$A$50:$A$66,$A19) -> 69890.687 | ... AI19: =AH19+SUMIFS(AH$50:AH$66,$A$50:$A$66,$A19) -> 2235598.2
A22: Mfg | B22: Sum of TOTAL | K22: Total
A23: Audi | B23: 0.013942247 | G23: Mfg | H23: Sum of JAN | I23: Sum of FEB | J23: Sum of MAR | K23: =SUM(H23:J23) -> 0
A24: BMW | B24: 0.050817957 | G24: Audi | H24: 175 | I24: 210 | J24: 45 | K24: =SUM(H24:J24) -> 430
A25: FCA | B25: 0.0024529697 | G25: BMW | H25: 997 | I25: 1111 | J25: 1147 | K25: =SUM(H25:J25) -> 3255
A26: Ford | B26: 0.026432552 | G26: FCA | H26: 72 | I26: 87 | J26: 33 | K26: =SUM(H26:J26) -> 192
A27: GM | B27: 0.10924734 | G27: Ford | H27: 557 | I27: 573 | J27: 611 | K27: =SUM(H27:J27) -> 1741
A28: Honda | B28: 0.053397183 | G28: GM | H28: 2044 | I28: 2430 | J28: 3782 | K28: =SUM(H28:J28) -> 8256
A29: Hyundai | B29: 0.0089280883 | G29: Honda | H29: 1270 | I29: 1281 | J29: 1403 | K29: =SUM(H29:J29) -> 3954
A30: Jaguar | B30: 0.0096766048 | G30: Hyundai | H30: 111 | I30: 173 | J30: 256 | K30: =SUM(H30:J30) -> 540
A31: Kia | B31: 0.016277979 | G31: Jaguar | H31: 210 | I31: 186 | J31: 212 | K31: =SUM(H31:J31) -> 608
A32: Mercedes | B32: 0.025224104 | G32: Kia | H32: 309 | I32: 517 | J32: 240 | K32: =SUM(H32:J32) -> 1066
A33: Mitsubishi | B33: 0.0092527461 | G33: Mercedes | H33: 398 | I33: 382 | J33: 532 | K33: =SUM(H33:J33) -> 1312
A34: Nissan | B34: 0.043756651 | G34: Mitsubishi | H34: 133 | I34: 157 | J34: 341 | K34: =SUM(H34:J34) -> 631
A35: Porsche | B35: 0.011543387 | G35: Nissan | H35: 717 | I35: 654 | J35: 1314 | K35: =SUM(H35:J35) -> 2685
A36: Subaru | B36: 0.0017224898 | G36: Porsche | H36: 215 | I36: 255 | J36: 310 | K36: =SUM(H36:J36) -> 780
A37: Tesla | B37: 0.52463792 | G37: Subaru | I37: 27 | J37: 52 | K37: =SUM(H37:J37) -> 79
A38: Toyota | B38: 0.06728532 | G38: Tesla | H38: 8000 | I38: 7275 | J38: 14625 | K38: =SUM(H38:J38) -> 29900
A39: Volvo | B39: 0.01163357 | G39: Toyota | H39: 1123 | I39: 1205 | J39: 1820 | K39: =SUM(H39:J39) -> 4148
A40: VW | B40: 0.0137709 | G40: Volvo | H40: 220 | I40: 250 | J40: 335 | K40: =SUM(H40:J40) -> 805
A41: Grand Total | B41: 1 | G41: VW | H41: 164 | I41: 118 | J41: 581 | K41: =SUM(H41:J41) -> 863
A44: BAU Projected Sales
A45: Time (Year) | B45: 2018 | C45: 2019 | D45: 2020 | E45: 2021 | F45: 2022 | G45: 2023 | H45: 2024 | I45: 2025 | J45: 2026 | K45: 2027 | L45: 2028 | M45: 2029 | N45: 2030 | O45: 2031 | P45: 2032 | Q45: 2033 | R45: 2034 | S45: 2035 | T45: 2036 | U45: 2037 | V45: 2038 | W45: 2039 | X45: 2040 | Y45: 2041 | Z45: 2042 | AA45: 2043 | AB45: 2044 | AC45: 2045 | AD45: 2046 | AE45: 2047 | AF45: 2048 | AG45: 2049 | AH45: 2050
...

Sheet 2019 Sales
A2: Mfg | B2: Type | C2: 2019 U.S. EV SALES | D2: JAN | E2: FEB | F2: MAR | G2: APR | H2: MAY | I2: JUN | J2: JUL | K2: AUG | L2: SEP | M2: OCT | N2: NOV | O2: DEC | P2: TOTAL
A3: Tesla | B3: BEV | C3: Tesla Model 3* 🔋 | D3: 6500 | E3: 5750 | F3: 10175 | G3: 10050 | H3: 13950 | P3: 46425 | Q3: Tesla Model 3* 🔋
A4: Toyota | B4: PHEV | C4: Toyota Prius Prime* | D4: 1123 | E4: 1205 | F4: 1820 | G4: 1399 | H4: 1914 | P4: 7461 | Q4: Toyota Prius Prime*
A5: GM | B5: BEV | C5: Chevrolet Bolt EV* 🔋 | D5: 925 | E5: 1225 | F5: 2166 | G5: 910 | H5: 1396 | P5: 6622 | Q5: Chevrolet Bolt EV* 🔋
A6: Tesla | B6: BEV | C6: Tesla Model X* 🔋 | D6: 775 | E6: 900 | F6: 2175 | G6: 1050 | H6: 1375 | P6: 6275 | Q6: Tesla Model X* 🔋
A7: Honda | B7: PHEV | C7: Honda Clarity PHEV* | D7: 1192 | E7: 1213 | F7: 1311 | G7: 981 | H7: 816 | P7: 5513 | Q7: Honda Clarity PHEV*
A8: Tesla | B8: BEV | C8: Tesla Model S* 🔋 | D8: 725 | E8: 625 | F8: 2275 | G8: 825 | H8: 1025 | P8: 5475 | Q8: Tesla Model S* 🔋
A9: Nissan | B9: BEV | C9: Nissan LEAF 🔋 | D9: 717 | E9: 654 | F9: 1314 | G9: 951 | H9: 1216 | P9: 4852 | Q9: Nissan LEAF 🔋
A10: GM | B10: PHEV | C10: Chevrolet Volt* | D10: 675 | E10: 615 | F10: 1230 | G10: 405 | H10: 408 | P10: 3333 | Q10: Chevrolet Volt*
A11: BMW | B11: PHEV | C11: BMW 530e* | D11: 376 | E11: 414 | F11: 436 | G11: 416 | H11: 727 | P11: 2369 | Q11: BMW 530e*
A12: Ford | B12: PHEV | C12: Ford Fusion Energi* | D12: 557 | E12: 573 | F12: 611 | G12: 585 | H12: 605 | P12: 2931 | Q12: Ford Fusion Energi*
A13: GM | B13: PHEV | C13: FCA Pacifica Hybrid* | D13: 436 | E13: 589 | F13: 383 | G13: 347 | H13: 390 | P13: 2145 | Q13: FCA Pacifica Hybrid*
A14: BMW | B14: BEV | C14: BMW i3 (BEV 🔋 + REx) | D14: 255 | E14: 350 | F14: 359 | G14: 331 | H14: 439 | P14: 1734 | Q14: BMW i3 (BEV 🔋 + REx)
... A17: Jaguar | B17: BEV | C17: Jaguar I-Pace 🔋 | D17: 210 | E17: 186 | F17: 212 | G17: 237 | H17: 228 | P17: 1073 | Q17: Jaguar I-Pace 🔋
A18: Audi | B18: BEV | C18: Audi e-tron 🔋 | G18: 253 | H18: 856 | P18: 1109 | Q18: Audi e-tron 🔋
A19: Mitsubishi | B19: PHEV | C19: Mitsubishi Outlander PHEV | D19: 133 | E19: 157 | F19: 341 | G19: 163 | H19: 232 | P19: 1026 | Q19: Mitsubishi Outlander PHEV
A20: Porsche | B20: PHEV | C20: Porsche Panamera E-Hybrid* | D20: 150 | E20: 160 | F20: 195 | G20: 155 | H20: 170 | P20: 830 | Q20: Porsche Panamera E-Hybrid*
A21: BMW | B21: PHEV | C21: BMW 330e* | D21: 216 | E21: 185 | F21: 175 | G21: 53 | H21: 27 | P21: 656 | Q21: BMW 330e*
A22: Mercedes | B22: PHEV | C22: Mercedes C350e* | D22: 140 | E22: 145 | F22: 135 | G22: 173 | H22: 225 | P22: 818 | Q22: Mercedes C350e*
A23: Volvo | B23: PHEV | C23: Volvo XC90 T8 PHEV* | D23: 95 | E23: 105 | F23: 155 | G23: 100 | H23: 120 | P23: 575 | Q23: Volvo XC90 T8 PHEV*
A24: Mercedes | B24: PHEV | C24: Mercedes GLC 350e* | D24: 74 | E24: 72 | F24: 175 | G24: 220 | H24: 275 | P24: 816 | Q24: Mercedes GLC 350e*
A25: Volvo | B25: PHEV | C25: Volvo XC60 PHEV* | D25: 90 | E25: 100 | F25: 125 | G25: 85 | H25: 95 | P25: 495 | Q25: Volvo XC60 PHEV*
A26: Porsche | B26: PHEV | C26: Porsche Cayenne S-E* | D26: 65 | E26: 95 | F26: 115 | G26: 70 | H26: 105 | P26: 450 | Q26: Porsche Cayenne S-E*
A27: Mercedes | B27: PHEV | C27: Mercedes GLE 550e* | D27: 92 | E27: 95 | F27: 110 | G27: 150 | H27: 185 | P27: 632 | Q27: Mercedes GLE 550e*
A28: Audi | B28: PHEV | C28: Audi A3 Sportback e-tron* | D28: 175 | E28: 210 | F28: 45 | G28: 7 | H28: 0 | P28: 437 | Q28: Audi A3 Sportback e-tron*
A29: Honda | B29: BEV | C29: Honda Clarity BEV* 🔋 | D29: 78 | E29: 68 | F29: 92 | G29: 88 | H29: 82 | P29: 408 | Q29: Honda Clarity BEV* 🔋
A30: BMW | B30: PHEV | C30: BMW i8 | D30: 23 | E30: 47 | F30: 91 | G30: 87 | H30: 145 | P30: 393 | Q30: BMW i8
... A36: Volvo | B36: PHEV | C36: Volvo S90 T8 PHEV* | D36: 35 | E36: 45 | F36: 55 | G36: 35 | H36: 50 | P36: 220 | Q36: Volvo S90 T8 PHEV*
A37: Subaru | B37: PHEV | C37: Subaru Crosstrek Hybrid* | E37: 27 | F37: 52 | G37: 47 | H37: 65 | P37: 191 | Q37: Subaru Crosstrek Hybrid*
A38: Hyundai | B38: PHEV | C38: Hyundai Sonata PHEV* | D38: 4 | E38: 71 | F38: 7 | G38: 46 | H38: 40 | P38: 168 | Q38: Hyundai Sonata PHEV*
A39: Hyundai | B39: BEV | C39: Hyundai IONIQ EV* 🔋 | D39: 34 | E39: 32 | F39: 28 | G39: 9 | H39: 61 | P39: 164 | Q39: Hyundai IONIQ EV* 🔋
A40: Kia | B40: BEV | C40: Kia Niro EV* 🔋 | G40: 40 | H40: 119 | P40: 159 | Q40: Kia Niro EV* 🔋
A41: BMW | B41: PHEV | C41: BMWX5 xDrive 40e* | D41: 71 | E41: 38 | F41: 26 | G41: 9 | H41: 4 | P41: 148 | Q41: BMWX5 xDrive 40e*
A42: Mercedes | B42: PHEV | C42: Mercedes S550e* | D42: 8 | E42: 10 | F42: 22 | G42: 35 | H42: 51 | P42: 126 | Q42: Mercedes S550e*
A43: BMW | B43: PHEV | C43: BMW 740e* | D43: 6 | E43: 14 | F43: 15 | G43: 8 | H43: 12 | P43: 55 | Q43: BMW 740e*
A44: Kia | B44: PHEV | C44: Kia Optima PHEV | D44: 30 | E44: 11 | F44: 8 | G44: 5 | H44: 0 | P44: 54 | Q44: Kia Optima PHEV
A45: GM | B45: PHEV | C45: Cadillac CT6 PHEV* | D45: 8 | E45: 1 | F45: 3 | G45: 2 | H45: 0 | P45: 14 | Q45: Cadillac CT6 PHEV*
A46: Mercedes | B46: PHEV | C46: Mercedes B250e* | D46: 1 | E46: 2 | F46: 0 | G46: 1 | H46: 0 | P46: 4 | Q46: Mercedes B250e*
A47: Kia | B47: BEV | C47: Kia Soul EV* 🔋 | D47: 0 | E47: 1 | F47: 2 | G47: 0 | H47: 1 | P47: 4 | Q47: Kia Soul EV* 🔋
C48: 2019 U.S. Sales Totals* | D48: 16715 | E48: 16891 | F48: 27639 | G48: 21255 | H48: 28386 | P48: 110886 | Q48: 2019 U.S. Sales Totals*
...

Sheet Cumulative Sales
A1: Manufacturer* | B1: Total Sales | C1: # To | D1: Reached /
B2: 2010 - Mar. 2019** | C2: Reach | D2: Likely
C3: 200000 | D3: to Reach
D4: 200000
A5: Audi | B5: 10218 | C5: 189782 | D5: 2025
A6: BMW | B6: 85888 | C6: 114112 | D6: 2023
A7: FCA | B7: 39855 | C7: 160145 | D7: 2025
A8: Ford | B8: 114247 | C8: 88753 | D8: 2023
A9: GM | B9: 211587 | C9: -11587 | D9: 2018 Q4
A10: Honda | B10: 27636 | C10: 172364 | D10: 2025
A11: Hyundai | B11: 9157 | C11: 190843 | D11: 2025
A12: Jaguar | B12: 1001 | C12: 198999 | D12: 2027
A13: Kia | B13: 13325 | C13: 186675 | D13: 2025
A14: Mercedes | B14: 19193 | C14: 180807 | D14: 2024
A15: Mitsubishi | B15: 7004 | C15: 192996 | D15: 2025
A16: Nissan | B16: 132227 | C16: 67773 | D16: 2021
A17: Porsche | B17: 10712 | C17: 189288 | D17: 2025
A18: Tesla | B18: 382573 | C18: -182573 | D18: 2018 Q3
A19: Toyota | B19: 99918 | C19: 100082 | D19: 2021
A20: Volvo | B20: 9841 | C20: 190159 | D20: 2024
A21: VW | B21: 14277 | C21: 185723 | D21: 2023

Sheet BESP-passengers
A1: Subsidy Percentage (dimensionless) | B1: 2016 | C1: 2017 | D1: 2018 | E1: 2019 | F1: 2020 | G1: 2021 | H1: 2022 | I1: 2023 | J1: 2024 | K1: 2025 | L1: 2026 | M1: 2027 | N1: 2028 | O1: 2029 | P1: 2030 | Q1: 2031 | R1: 2032 | S1: 2033 | T1: 2034 | U1: 2035 | V1: 2036 | W1: 2037 | X1: 2038 | Y1: 2039 | Z1: 2040 | AA1: 2041 | AB1: 2042 | AC1: 2043 | AD1: 2044 | AE1: 2045 | AF1: 2046 | AG1: 2047 | AH1: 2048 | AI1: 2049 | AJ1: 2050
A2: LDVs | B2: =C2 -> 4653.6589 | C2: =D2 -> 4653.6589 | D2: =E2 -> 4653.6589 | E2: =Data!A33*About!$A45 -> 4653.6589 | F2: =Data!B33*About!$A45 -> 4653.6589 | G2: =Data!C33*About!$A45 -> 4653.6589 | H2: =Data!D33*About!$A45 -> 3914.8601 | I2: =Data!E33*About!$A45 -> 3576.7514 | J2: =Data!F33*About!$A45 -> 3221.4823 | K2: =Data!G33*About!$A45 -> 3045.6178 | L2: =Data!H33*About!$A45 -> 3045.6178 | ... AJ2: =Data!AF33*About!$A45 -> 0
A3: HDVs | B3: 0 | C3: 0 | D3: 0 | E3: 0 | F3: =Data!B35 -> 0 | G3: =Data!C35 -> 0 | H3: =Data!D35 -> 0 | I3: =Data!E35 -> 0 | J3: =Data!F35 -> 0 | K3: =Data!G35 -> 0 | L3: =Data!H35 -> 0 | M3: 0 | N3: 0 | O3: 0 | P3: 0 | Q3: 0 | R3: 0 | S3: 0 | T3: 0 | U3: 0 | V3: 0 | W3: 0 | X3: 0 | Y3: 0 | Z3: 0 | AA3: 0 | AB3: 0 | AC3: 0 | AD3: 0 | AE3: 0 | AF3: 0 | AG3: 0 | AH3: 0 | AI3: 0 | AJ3: 0
A4: aircraft | B4: 0 | C4: 0 | D4: 0 | E4: 0 | F4: 0 | G4: 0 | H4: 0 | I4: 0 | J4: 0 | K4: 0 | L4: 0 | M4: 0 | N4: 0 | O4: 0 | P4: 0 | Q4: 0 | R4: 0 | S4: 0 | T4: 0 | U4: 0 | V4: 0 | W4: 0 | X4: 0 | Y4: 0 | Z4: 0 | AA4: 0 | AB4: 0 | AC4: 0 | AD4: 0 | AE4: 0 | AF4: 0 | AG4: 0 | AH4: 0 | AI4: 0 | AJ4: 0
A5: rail | B5: 0 | C5: 0 | D5: 0 | E5: 0 | F5: 0 | G5: 0 | H5: 0 | I5: 0 | J5: 0 | K5: 0 | L5: 0 | M5: 0 | N5: 0 | O5: 0 | P5: 0 | Q5: 0 | R5: 0 | S5: 0 | T5: 0 | U5: 0 | V5: 0 | W5: 0 | X5: 0 | Y5: 0 | Z5: 0 | AA5: 0 | AB5: 0 | AC5: 0 | AD5: 0 | AE5: 0 | AF5: 0 | AG5: 0 | AH5: 0 | AI5: 0 | AJ5: 0
A6: ships | B6: 0 | C6: 0 | D6: 0 | E6: 0 | F6: 0 | G6: 0 | H6: 0 | I6: 0 | J6: 0 | K6: 0 | L6: 0 | M6: 0 | N6: 0 | O6: 0 | P6: 0 | Q6: 0 | R6: 0 | S6: 0 | T6: 0 | U6: 0 | V6: 0 | W6: 0 | X6: 0 | Y6: 0 | Z6: 0 | AA6: 0 | AB6: 0 | AC6: 0 | AD6: 0 | AE6: 0 | AF6: 0 | AG6: 0 | AH6: 0 | AI6: 0 | AJ6: 0
A7: motorbikes | B7: 0 | C7: 0 | D7: 0 | E7: 0 | F7: 0 | G7: 0 | H7: 0 | I7: 0 | J7: 0 | K7: 0 | L7: 0 | M7: 0 | N7: 0 | O7: 0 | P7: 0 | Q7: 0 | R7: 0 | S7: 0 | T7: 0 | U7: 0 | V7: 0 | W7: 0 | X7: 0 | Y7: 0 | Z7: 0 | AA7: 0 | AB7: 0 | AC7: 0 | AD7: 0 | AE7: 0 | AF7: 0 | AG7: 0 | AH7: 0 | AI7: 0 | AJ7: 0

Sheet BESP-freight
A1: Subsidy Percentage (dimensionless) | B1: 2016 | C1: 2017 | D1: 2018 | E1: 2019 | F1: 2020 | G1: 2021 | H1: 2022 | I1: 2023 | J1: 2024 | K1: 2025 | L1: 2026 | M1: 2027 | N1: 2028 | O1: 2029 | P1: 2030 | Q1: 2031 | R1: 2032 | S1: 2033 | T1: 2034 | U1: 2035 | V1: 2036 | W1: 2037 | X1: 2038 | Y1: 2039 | Z1: 2040 | AA1: 2041 | AB1: 2042 | AC1: 2043 | AD1: 2044 | AE1: 2045 | AF1: 2046 | AG1: 2047 | AH1: 2048 | AI1: 2049 | AJ1: 2050
A2: LDVs | B2: 0 | C2: 0 | D2: 0 | E2: 0 | F2: 0 | G2: 0 | H2: 0 | I2: 0 | J2: 0 | K2: 0 | L2: 0 | M2: 0 | N2: 0 | O2: 0 | P2: 0 | Q2: 0 | R2: 0 | S2: 0 | T2: 0 | U2: 0 | V2: 0 | W2: 0 | X2: 0 | Y2: 0 | Z2: 0 | AA2: 0 | AB2: 0 | AC2: 0 | AD2: 0 | AE2: 0 | AF2: 0 | AG2: 0 | AH2: 0 | AI2: 0 | AJ2: 0
A3: HDVs | B3: 0 | C3: 0 | D3: 0 | E3: 0 | F3: 0 | G3: 0 | H3: 0 | I3: 0 | J3: 0 | K3: 0 | L3: 0 | M3: 0 | N3: 0 | O3: 0 | P3: 0 | Q3: 0 | R3: 0 | S3: 0 | T3: 0 | U3: 0 | V3: 0 | W3: 0 | X3: 0 | Y3: 0 | Z3: 0 | AA3: 0 | AB3: 0 | AC3: 0 | AD3: 0 | AE3: 0 | AF3: 0 | AG3: 0 | AH3: 0 | AI3: 0 | AJ3: 0
A4: aircraft | B4: 0 | C4: 0 | D4: 0 | E4: 0 | F4: 0 | G4: 0 | H4: 0 | I4: 0 | J4: 0 | K4: 0 | L4: 0 | M4: 0 | N4: 0 | O4: 0 | P4: 0 | Q4: 0 | R4: 0 | S4: 0 | T4: 0 | U4: 0 | V4: 0 | W4: 0 | X4: 0 | Y4: 0 | Z4: 0 | AA4: 0 | AB4: 0 | AC4: 0 | AD4: 0 | AE4: 0 | AF4: 0 | AG4: 0 | AH4: 0 | AI4: 0 | AJ4: 0
A5: rail | B5: 0 | C5: 0 | D5: 0 | E5: 0 | F5: 0 | G5: 0 | H5: 0 | I5: 0 | J5: 0 | K5: 0 | L5: 0 | M5: 0 | N5: 0 | O5: 0 | P5: 0 | Q5: 0 | R5: 0 | S5: 0 | T5: 0 | U5: 0 | V5: 0 | W5: 0 | X5: 0 | Y5: 0 | Z5: 0 | AA5: 0 | AB5: 0 | AC5: 0 | AD5: 0 | AE5: 0 | AF5: 0 | AG5: 0 | AH5: 0 | AI5: 0 | AJ5: 0
A6: ships | B6: 0 | C6: 0 | D6: 0 | E6: 0 | F6: 0 | G6: 0 | H6: 0 | I6: 0 | J6: 0 | K6: 0 | L6: 0 | M6: 0 | N6: 0 | O6: 0 | P6: 0 | Q6: 0 | R6: 0 | S6: 0 | T6: 0 | U6: 0 | V6: 0 | W6: 0 | X6: 0 | Y6: 0 | Z6: 0 | AA6: 0 | AB6: 0 | AC6: 0 | AD6: 0 | AE6: 0 | AF6: 0 | AG6: 0 | AH6: 0 | AI6: 0 | AJ6: 0
A7: motorbikes | B7: 0 | C7: 0 | D7: 0 | E7: 0 | F7: 0 | G7: 0 | H7: 0 | I7: 0 | J7: 0 | K7: 0 | L7: 0 | M7: 0 | N7: 0 | O7: 0 | P7: 0 | Q7: 0 | R7: 0 | S7: 0 | T7: 0 | U7: 0 | V7: 0 | W7: 0 | X7: 0 | Y7: 0 | Z7: 0 | AA7: 0 | AB7: 0 | AC7: 0 | AD7: 0 | AE7: 0 | AF7: 0 | AG7: 0 | AH7: 0 | AI7: 0 | AJ7: 0
